Unsupported operator aten::add encountered 33 time(s)
Unsupported operator aten::mul encountered 25 time(s)
Unsupported operator aten::softmax encountered 12 time(s)
Unsupported operator aten::gelu encountered 21 time(s)
Unsupported operator aten::sum encountered 6 time(s)
Unsupported operator aten::div encountered 3 time(s)
Unsupported operator aten::log_softmax encountered 3 time(s)
Unsupported operator aten::argsort encountered 3 time(s)
The following submodules of the model were never called during the trace of the graph. They may be unused, or they were accessed by direct calls to .forward() or via other python methods. In the latter case they will have zeros for statistics, though their statistics will still contribute to their parent calling module.
blocks.0.attn.attn_drop, blocks.1.attn.attn_drop, blocks.1.drop_path, blocks.10.attn.attn_drop, blocks.10.drop_path, blocks.11.attn.attn_drop, blocks.11.drop_path, blocks.2.attn.attn_drop, blocks.2.drop_path, blocks.3.attn.attn_drop, blocks.3.drop_path, blocks.4.attn.attn_drop, blocks.4.drop_path, blocks.5.attn.attn_drop, blocks.5.drop_path, blocks.6.attn.attn_drop, blocks.6.drop_path, blocks.7.attn.attn_drop, blocks.7.drop_path, blocks.8.attn.attn_drop, blocks.8.drop_path, blocks.9.attn.attn_drop, blocks.9.drop_path
Traceback (most recent call last):
  File "/nfs/hpc/share/buivy/pruning-vision-transformers/DynamicViT/main.py", line 628, in <module>
  File "/nfs/hpc/share/buivy/pruning-vision-transformers/DynamicViT/main.py", line 558, in main
    device, epoch, loss_scaler, args.clip_grad, model_ema, mixup_fn,
  File "/nfs/hpc/share/buivy/pruning-vision-transformers/DynamicViT/engine.py", line 66, in train_one_epoch
    assert math.isfinite(loss_value)
AssertionError
ERROR:torch.distributed.elastic.multiprocessing.api:failed (exitcode: 1) local_rank: 0 (pid: 39060) of binary: /nfs/hpc/share/buivy/trustworthy-machine-learning/venv/bin/python3
Traceback (most recent call last):
  File "/nfs/hpc/share/buivy/trustworthy-machine-learning/venv/bin/torchrun", line 8, in <module>
    sys.exit(main())
  File "/nfs/hpc/share/buivy/trustworthy-machine-learning/venv/lib/python3.10/site-packages/torch/distributed/elastic/multiprocessing/errors/__init__.py", line 346, in wrapper
    return f(*args, **kwargs)
  File "/nfs/hpc/share/buivy/trustworthy-machine-learning/venv/lib/python3.10/site-packages/torch/distributed/run.py", line 794, in main
    run(args)
  File "/nfs/hpc/share/buivy/trustworthy-machine-learning/venv/lib/python3.10/site-packages/torch/distributed/run.py", line 785, in run
    elastic_launch(
  File "/nfs/hpc/share/buivy/trustworthy-machine-learning/venv/lib/python3.10/site-packages/torch/distributed/launcher/api.py", line 134, in __call__
    return launch_agent(self._config, self._entrypoint, list(args))
  File "/nfs/hpc/share/buivy/trustworthy-machine-learning/venv/lib/python3.10/site-packages/torch/distributed/launcher/api.py", line 250, in launch_agent
    raise ChildFailedError(
torch.distributed.elastic.multiprocessing.errors.ChildFailedError: 
============================================================
main.py FAILED
------------------------------------------------------------
Failures:
  <NO_OTHER_FAILURES>
------------------------------------------------------------
Root Cause (first observed failure):
[0]:
  time      : 2023-06-12_23:13:01
  host      : cn-r-3.hpc.engr.oregonstate.edu
  rank      : 0 (local_rank: 0)
  exitcode  : 1 (pid: 39060)
  error_file: <N/A>
  traceback : To enable traceback see: https://pytorch.org/docs/stable/elastic/errors.html
============================================================
